<?xml version="1.0"?>
<robot name="itls_robot"
  xmlns:xacro="http://www.ros.org/wiki/xacro">

  <!--Wheels Constants-->
  <xacro:property name="wheel_radius" value="0.14"/>
  <xacro:property name="wheel_width" value="0.2"/>
  <xacro:property name="wheel_ygap" value="0.07"/>
  <xacro:property name="wheel_zoff" value="0.0"/>
  <xacro:property name="wheel_xoff" value="-0.5"/>

  <!-- Wheels Xacro and instances -->
  <xacro:macro name="wheel" params="prefix x_reflect y_reflect fixedOrCont">
    <link name="${prefix}_link">
      <visual>
        <origin xyz="0 0 0" rpy="${pi/2} 0 0"/>
        <geometry>
          <cylinder radius="${wheel_radius}" length="${wheel_width}"/>
        </geometry>
        <material name="Black">
          <color rgba="0 0 0 1"/>
        </material>
      </visual>
      <collision>
        <origin xyz="0 0 0" rpy="${pi/2} 0 0"/>
        <geometry>
          <cylinder radius="${wheel_radius}" length="${wheel_width}"/>
        </geometry>
      </collision>
      <xacro:cylinder_inertia m="0.5" r="${wheel_radius}" h="${wheel_width}"/>
    </link>
    <joint name="base_link_T_${prefix}" type="${fixedOrCont}">
      <parent link="base_link"/>
      <child link="${prefix}_link"/>
      <origin xyz="${x_reflect*(wheel_xoff + (base_length_actual/2))} ${y_reflect*(base_width/2+wheel_ygap)} ${wheel_zoff}" rpy="0 0 0"/>
      <axis xyz="0 1 0"/>
    </joint>
  </xacro:macro>
  <!-- <xacro:wheel fixedOrCont="continuous" prefix="frontwhl_l" x_reflect="1" y_reflect="1" /> -->
  <!-- <xacro:wheel fixedOrCont="continuous" prefix="frontwhl_r" x_reflect="1" y_reflect="-1" /> -->
  <xacro:wheel fixedOrCont="continuous" prefix="rearwhl_l" x_reflect="-1" y_reflect="1" />
  <xacro:wheel fixedOrCont="continuous" prefix="rearwhl_r" x_reflect="-1" y_reflect="-1" />


  <joint name="caster_wheel_joint" type="continuous">
    <parent link="base_link"/>
    <child link="caster_wheel"/>
    <origin xyz="1.2 0 0"/>
  </joint>

  <link name="caster_wheel">
    <visual>
      <geometry>
        <sphere radius="${wheel_radius}"/>
      </geometry>
      <material name="Black">
        <color rgba="0 0 0 1"/>
      </material>
    </visual>
    <collision>
      <geometry>
        <sphere radius="${wheel_radius}"/>
      </geometry>
    </collision>
    <xacro:inertial_sphere mass="0.1" radius="${wheel_radius}">
      <origin xyz="0 0 0" rpy="0 0 0"/>
    </xacro:inertial_sphere>
  </link>

  <!-- <gazebo reference="caster_wheel">
    <material>Gazebo/Black</material>
    <mu1 value="0.1"/>
    <mu2 value="0.1"/>
  </gazebo> -->

</robot>