<?xml version="1.0" ?>
<!-- =================================================================================== -->
<!-- |    This document was autogenerated by xacro from ./src/itls_robot_description/config/itls_main.urdf.xacro | -->
<!-- |    EDITING THIS FILE BY HAND IS NOT RECOMMENDED                                 | -->
<!-- =================================================================================== -->
<robot name="itls_robot">
  <!-- Robot Base -->
  <link name="base_link">
    <origin rpy="0.0 0.0 1.5707963267948966" xyz="0.0 0.0 0.14"/>
  </link>
  <link name="robot_center">
    <visual>
      <geometry>
        <box size="2.64 1.3005 1.3"/>
      </geometry>
      <material name="Orange">
        <color rgba="1.0 0.5 0 1.0"/>
      </material>
    </visual>
    <collision>
      <geometry>
        <box size="2.64 1.3005 1.3"/>
      </geometry>
    </collision>
    <inertial>
      <origin rpy="1.5707963267948966 0 1.5707963267948966" xyz="0 0 0"/>
      <mass value="1500"/>
      <inertia ixx="2349.5620000000004" ixy="0.0" ixz="0.0" iyy="2349.72453125" iyz="0.0" izz="422.66253125000003"/>
    </inertial>
  </link>
  <joint name="base_link_T_robot_center" type="fixed">
    <parent link="base_link"/>
    <child link="robot_center"/>
    <origin rpy="0.0 0.0 0.0" xyz="0.040000000000000036 0.0 0.65025"/>
  </joint>
  <link name="base_link_front"> </link>
  <joint name="base_link_T_base_link_front" type="fixed">
    <parent link="base_link"/>
    <child link="base_link_front"/>
    <origin rpy="0.0 0.0 0.0" xyz="2.3715 0.0 0.0"/>
  </joint>
  <link name="base_link_back"> </link>
  <joint name="base_link_T_base_link_back" type="fixed">
    <parent link="base_link"/>
    <child link="base_link_back"/>
    <origin rpy="0.0 0.0 3.141592653589793" xyz="-1.7645 0.0 0.0"/>
  </joint>
  <!-- Robot Footprint -->
  <link name="base_footprint"/>
  <joint name="base_joint" type="fixed">
    <parent link="base_link"/>
    <child link="base_footprint"/>
    <origin rpy="0 0 0" xyz="0.0 0.0 -0.14"/>
  </joint>
  <!-- keep in mind if there is problem in slippery between Gazebo and RVIZ 
  you can change the collision gemetry of the wheels into sphere without toaching the visuals
  Last time I checked the rotation it is pretty good no need -->
  <link name="frontwhl_l_link">
    <visual>
      <origin rpy="1.5707963267948966 0 0" xyz="0 0 0"/>
      <geometry>
        <cylinder length="0.2" radius="0.14"/>
      </geometry>
      <material name="Black">
        <color rgba="0 0 0 1"/>
      </material>
    </visual>
    <collision>
      <origin rpy="1.5707963267948966 0 0" xyz="0 0 0"/>
      <geometry>
        <cylinder length="0.2" radius="0.14"/>
      </geometry>
    </collision>
    <inertial>
      <origin rpy="1.5707963267948966 0 0" xyz="0 0 0"/>
      <mass value="50"/>
      <inertia ixx="0.4116666666666668" ixy="0" ixz="0" iyy="0.4116666666666668" iyz="0" izz="0.49000000000000005"/>
    </inertial>
  </link>
  <joint name="frontwhl_l_joint" type="continuous">
    <parent link="base_link"/>
    <child link="frontwhl_l_link"/>
    <origin rpy="0 0 0" xyz="1.1600000000000001 0.7202500000000001 0.0"/>
    <axis xyz="0 1 0"/>
  </joint>
  <link name="frontwhl_r_link">
    <visual>
      <origin rpy="1.5707963267948966 0 0" xyz="0 0 0"/>
      <geometry>
        <cylinder length="0.2" radius="0.14"/>
      </geometry>
      <material name="Black">
        <color rgba="0 0 0 1"/>
      </material>
    </visual>
    <collision>
      <origin rpy="1.5707963267948966 0 0" xyz="0 0 0"/>
      <geometry>
        <cylinder length="0.2" radius="0.14"/>
      </geometry>
    </collision>
    <inertial>
      <origin rpy="1.5707963267948966 0 0" xyz="0 0 0"/>
      <mass value="50"/>
      <inertia ixx="0.4116666666666668" ixy="0" ixz="0" iyy="0.4116666666666668" iyz="0" izz="0.49000000000000005"/>
    </inertial>
  </link>
  <joint name="frontwhl_r_joint" type="continuous">
    <parent link="base_link"/>
    <child link="frontwhl_r_link"/>
    <origin rpy="0 0 0" xyz="1.1600000000000001 -0.7202500000000001 0.0"/>
    <axis xyz="0 1 0"/>
  </joint>
  <link name="rearwhl_l_link">
    <visual>
      <origin rpy="1.5707963267948966 0 0" xyz="0 0 0"/>
      <geometry>
        <cylinder length="0.2" radius="0.14"/>
      </geometry>
      <material name="Black">
        <color rgba="0 0 0 1"/>
      </material>
    </visual>
    <collision>
      <origin rpy="1.5707963267948966 0 0" xyz="0 0 0"/>
      <geometry>
        <cylinder length="0.2" radius="0.14"/>
      </geometry>
    </collision>
    <inertial>
      <origin rpy="1.5707963267948966 0 0" xyz="0 0 0"/>
      <mass value="50"/>
      <inertia ixx="0.4116666666666668" ixy="0" ixz="0" iyy="0.4116666666666668" iyz="0" izz="0.49000000000000005"/>
    </inertial>
  </link>
  <joint name="rearwhl_l_joint" type="fixed">
    <parent link="base_link"/>
    <child link="rearwhl_l_link"/>
    <origin rpy="0 0 0" xyz="-1.1600000000000001 0.7202500000000001 0.0"/>
    <axis xyz="0 1 0"/>
  </joint>
  <link name="rearwhl_r_link">
    <visual>
      <origin rpy="1.5707963267948966 0 0" xyz="0 0 0"/>
      <geometry>
        <cylinder length="0.2" radius="0.14"/>
      </geometry>
      <material name="Black">
        <color rgba="0 0 0 1"/>
      </material>
    </visual>
    <collision>
      <origin rpy="1.5707963267948966 0 0" xyz="0 0 0"/>
      <geometry>
        <cylinder length="0.2" radius="0.14"/>
      </geometry>
    </collision>
    <inertial>
      <origin rpy="1.5707963267948966 0 0" xyz="0 0 0"/>
      <mass value="50"/>
      <inertia ixx="0.4116666666666668" ixy="0" ixz="0" iyy="0.4116666666666668" iyz="0" izz="0.49000000000000005"/>
    </inertial>
  </link>
  <joint name="rearwhl_r_joint" type="fixed">
    <parent link="base_link"/>
    <child link="rearwhl_r_link"/>
    <origin rpy="0 0 0" xyz="-1.1600000000000001 -0.7202500000000001 0.0"/>
    <axis xyz="0 1 0"/>
  </joint>
</robot>
